<sdf version='1.7'>
  <world name='CRANE-X7 with Table'>
    <scene>
      <shadows>0</shadows>
      <ambient>0.4 0.4 0.4 1</ambient>
      <background>0.7 0.7 0.7 1</background>
    </scene>
    <light name='sun' type='directional'>
      <cast_shadows>1</cast_shadows>
      <pose>0 0 10 0 -0 0</pose>
      <diffuse>0.8 0.8 0.8 1</diffuse>
      <specular>0.2 0.2 0.2 1</specular>
      <attenuation>
        <range>1000</range>
        <constant>0.9</constant>
        <linear>0.01</linear>
        <quadratic>0.001</quadratic>
      </attenuation>
      <direction>-0.5 0.1 -0.9</direction>
      <spot>
        <inner_angle>0</inner_angle>
        <outer_angle>0</outer_angle>
        <falloff>0</falloff>
      </spot>
    </light>
    <model name='table'>
      <frame name='table::__model__' attached_to='table::link'>
        <pose relative_to='__model__'>0 0 0 0 -0 0</pose>
      </frame>
      <static>1</static>
      <link name='table::link'>
        <collision name='surface'>
          <pose>0 0 1 0 -0 0</pose>
          <geometry>
            <box>
              <size>1.5 0.8 0.03</size>
            </box>
          </geometry>
          <surface>
            <friction>
              <ode>
                <mu>0.6</mu>
                <mu2>0.6</mu2>
              </ode>
              <torsional>
                <ode/>
              </torsional>
            </friction>
            <contact>
              <ode/>
            </contact>
            <bounce/>
          </surface>
          <max_contacts>10</max_contacts>
        </collision>
        <visual name='visual1'>
          <pose>0 0 1 0 -0 0</pose>
          <geometry>
            <box>
              <size>1.5 0.8 0.03</size>
            </box>
          </geometry>
          <material>
            <script>
              <uri>file://media/materials/scripts/gazebo.material</uri>
              <name>Gazebo/Wood</name>
            </script>
          </material>
        </visual>
        <collision name='front_left_leg'>
          <pose>0.68 0.38 0.5 0 -0 0</pose>
          <geometry>
            <cylinder>
              <radius>0.02</radius>
              <length>1</length>
            </cylinder>
          </geometry>
          <max_contacts>10</max_contacts>
          <surface>
            <contact>
              <ode/>
            </contact>
            <bounce/>
            <friction>
              <torsional>
                <ode/>
              </torsional>
              <ode/>
            </friction>
          </surface>
        </collision>
        <visual name='front_left_leg'>
          <pose>0.68 0.38 0.5 0 -0 0</pose>
          <geometry>
            <cylinder>
              <radius>0.02</radius>
              <length>1</length>
            </cylinder>
          </geometry>
          <material>
            <script>
              <uri>file://media/materials/scripts/gazebo.material</uri>
              <name>Gazebo/Grey</name>
            </script>
          </material>
        </visual>
        <collision name='front_right_leg'>
          <pose>0.68 -0.38 0.5 0 -0 0</pose>
          <geometry>
            <cylinder>
              <radius>0.02</radius>
              <length>1</length>
            </cylinder>
          </geometry>
          <max_contacts>10</max_contacts>
          <surface>
            <contact>
              <ode/>
            </contact>
            <bounce/>
            <friction>
              <torsional>
                <ode/>
              </torsional>
              <ode/>
            </friction>
          </surface>
        </collision>
        <visual name='front_right_leg'>
          <pose>0.68 -0.38 0.5 0 -0 0</pose>
          <geometry>
            <cylinder>
              <radius>0.02</radius>
              <length>1</length>
            </cylinder>
          </geometry>
          <material>
            <script>
              <uri>file://media/materials/scripts/gazebo.material</uri>
              <name>Gazebo/Grey</name>
            </script>
          </material>
        </visual>
        <collision name='back_right_leg'>
          <pose>-0.68 -0.38 0.5 0 -0 0</pose>
          <geometry>
            <cylinder>
              <radius>0.02</radius>
              <length>1</length>
            </cylinder>
          </geometry>
          <max_contacts>10</max_contacts>
          <surface>
            <contact>
              <ode/>
            </contact>
            <bounce/>
            <friction>
              <torsional>
                <ode/>
              </torsional>
              <ode/>
            </friction>
          </surface>
        </collision>
        <visual name='back_right_leg'>
          <pose>-0.68 -0.38 0.5 0 -0 0</pose>
          <geometry>
            <cylinder>
              <radius>0.02</radius>
              <length>1</length>
            </cylinder>
          </geometry>
          <material>
            <script>
              <uri>file://media/materials/scripts/gazebo.material</uri>
              <name>Gazebo/Grey</name>
            </script>
          </material>
        </visual>
        <collision name='back_left_leg'>
          <pose>-0.68 0.38 0.5 0 -0 0</pose>
          <geometry>
            <cylinder>
              <radius>0.02</radius>
              <length>1</length>
            </cylinder>
          </geometry>
          <max_contacts>10</max_contacts>
          <surface>
            <contact>
              <ode/>
            </contact>
            <bounce/>
            <friction>
              <torsional>
                <ode/>
              </torsional>
              <ode/>
            </friction>
          </surface>
        </collision>
        <visual name='back_left_leg'>
          <pose>-0.68 0.38 0.5 0 -0 0</pose>
          <geometry>
            <cylinder>
              <radius>0.02</radius>
              <length>1</length>
            </cylinder>
          </geometry>
          <material>
            <script>
              <uri>file://media/materials/scripts/gazebo.material</uri>
              <name>Gazebo/Grey</name>
            </script>
          </material>
        </visual>
        <pose relative_to='table::__model__'>0 0 0 0 -0 0</pose>
        <self_collide>0</self_collide>
        <enable_wind>0</enable_wind>
        <kinematic>0</kinematic>
      </link>
      <pose>0.29 0 0 0 -0 1.5708</pose>
    </model>
    <model name='ground_plane'>
      <frame name='ground_plane::__model__' attached_to='ground_plane::link'>
        <pose relative_to='__model__'>0 0 0 0 -0 0</pose>
      </frame>
      <static>1</static>
      <link name='ground_plane::link'>
        <collision name='collision'>
          <geometry>
            <plane>
              <normal>0 0 1</normal>
              <size>100 100</size>
            </plane>
          </geometry>
          <surface>
            <friction>
              <ode>
                <mu>100</mu>
                <mu2>50</mu2>
              </ode>
              <torsional>
                <ode/>
              </torsional>
            </friction>
            <contact>
              <ode/>
            </contact>
            <bounce/>
          </surface>
          <max_contacts>10</max_contacts>
        </collision>
        <visual name='visual'>
          <cast_shadows>0</cast_shadows>
          <geometry>
            <plane>
              <normal>0 0 1</normal>
              <size>100 100</size>
            </plane>
          </geometry>
          <material>
            <script>
              <uri>file://media/materials/scripts/gazebo.material</uri>
              <name>Gazebo/Grey</name>
            </script>
          </material>
        </visual>
        <pose relative_to='ground_plane::__model__'>0 0 0 0 -0 0</pose>
        <self_collide>0</self_collide>
        <enable_wind>0</enable_wind>
        <kinematic>0</kinematic>
      </link>
      <joint name='ground_joint' type='fixed'>
        <parent>ground_plane::link</parent>
        <child>table::link</child>
      </joint>
    </model>
    <gravity>0 0 -9.8</gravity>
    <magnetic_field>6e-06 2.3e-05 -4.2e-05</magnetic_field>
    <atmosphere type='adiabatic'/>
    <physics type='ode'>
      <max_step_size>0.001</max_step_size>
      <real_time_factor>1</real_time_factor>
      <real_time_update_rate>1000</real_time_update_rate>
    </physics>
    <wind/>
    <spherical_coordinates>
      <surface_model>EARTH_WGS84</surface_model>
      <latitude_deg>0</latitude_deg>
      <longitude_deg>0</longitude_deg>
      <elevation>0</elevation>
      <heading_deg>0</heading_deg>
    </spherical_coordinates>
    <model name='crane_x7'>
      <joint name='base_link_to_world_joint' type='fixed'>
        <pose relative_to='__model__'>0 0 0 0 -0 0</pose>
        <parent>world</parent>
        <child>base_link</child>
      </joint>
      <link name='base_link'>
        <pose relative_to='base_link_to_world_joint'>0 0 0 0 -0 0</pose>
        <inertial>
          <pose>-0.00673 -1e-06 0.0229 0 -0 0</pose>
          <mass>0.388</mass>
          <inertia>
            <ixx>0.000325</ixx>
            <ixy>1.2e-09</ixy>
            <ixz>-4.71e-05</ixz>
            <iyy>0.000483</iyy>
            <iyz>1.95e-08</iyz>
            <izz>0.000586</izz>
          </inertia>
        </inertial>
        <collision name='base_link_fixed_joint_lump__crane_x7_mounting_plate_link_collision'>
          <pose>0 0 0 0 -0 0</pose>
          <geometry>
            <mesh>
              <scale>1 1 1</scale>
              <uri>/home/shiokaze/catkin_ws/src/crane_x7_description/meshes/collision/mounting_plate.stl</uri>
            </mesh>
          </geometry>
          <surface>
            <contact>
              <ode/>
            </contact>
            <friction>
              <ode/>
              <torsional>
                <ode/>
              </torsional>
            </friction>
            <bounce/>
          </surface>
          <max_contacts>10</max_contacts>
        </collision>
        <collision name='base_link_fixed_joint_lump__crane_x7_shoulder_fixed_part_link_collision_1'>
          <pose>0 0 0.005 0 -0 0</pose>
          <geometry>
            <mesh>
              <scale>1 1 1</scale>
              <uri>/home/shiokaze/catkin_ws/src/crane_x7_description/meshes/collision/base_fixed_part.stl</uri>
            </mesh>
          </geometry>
          <surface>
            <contact>
              <ode/>
            </contact>
            <friction>
              <ode/>
              <torsional>
                <ode/>
              </torsional>
            </friction>
            <bounce/>
          </surface>
          <max_contacts>10</max_contacts>
        </collision>
        <visual name='base_link_fixed_joint_lump__crane_x7_mounting_plate_link_visual'>
          <pose>0 0 0 0 -0 0</pose>
          <geometry>
            <mesh>
              <scale>1 1 1</scale>
              <uri>/home/shiokaze/catkin_ws/src/crane_x7_description/meshes/visual/mounting_plate.stl</uri>
            </mesh>
          </geometry>
          <material>
            <script>
              <name>Gazebo/Black</name>
              <uri>file://media/materials/scripts/gazebo.material</uri>
            </script>
          </material>
        </visual>
        <visual name='base_link_fixed_joint_lump__crane_x7_shoulder_fixed_part_link_visual_1'>
          <pose>0 0 0.005 0 -0 0</pose>
          <geometry>
            <mesh>
              <scale>1 1 1</scale>
              <uri>/home/shiokaze/catkin_ws/src/crane_x7_description/meshes/visual/base_fixed_part.stl</uri>
            </mesh>
          </geometry>
          <material>
            <script>
              <name>Gazebo/Red</name>
              <uri>file://media/materials/scripts/gazebo.material</uri>
            </script>
          </material>
        </visual>
        <self_collide>0</self_collide>
        <enable_wind>0</enable_wind>
        <kinematic>0</kinematic>
      </link>
      <joint name='crane_x7_shoulder_fixed_part_pan_joint' type='revolute'>
        <pose relative_to='base_link'>0 0 0.041 0 -0 0</pose>
        <parent>base_link</parent>
        <child>crane_x7_shoulder_revolute_part_link</child>
        <axis>
          <xyz>0 0 1</xyz>
          <limit>
            <lower>-2.97132</lower>
            <upper>2.97132</upper>
            <effort>10</effort>
            <velocity>4.81711</velocity>
          </limit>
          <dynamics>
            <damping>1e-06</damping>
            <friction>0.2</friction>
            <spring_reference>0</spring_reference>
            <spring_stiffness>0</spring_stiffness>
          </dynamics>
        </axis>
      </joint>
      <link name='crane_x7_shoulder_revolute_part_link'>
        <pose relative_to='crane_x7_shoulder_fixed_part_pan_joint'>0 0 0 0 -0 0</pose>
        <inertial>
          <pose>0.000243 -0.000105 0.047 0 -0 0</pose>
          <mass>0.253</mass>
          <inertia>
            <ixx>0.000179</ixx>
            <ixy>-7.32e-08</ixy>
            <ixz>8.89e-07</ixz>
            <iyy>0.000176</iyy>
            <iyz>6.23e-07</iyz>
            <izz>8.96e-05</izz>
          </inertia>
        </inertial>
        <collision name='crane_x7_shoulder_revolute_part_link_collision'>
          <pose>0 0 0.0296 0 -0 0</pose>
          <geometry>
            <cylinder>
              <length>0.0295</length>
              <radius>0.0334</radius>
            </cylinder>
          </geometry>
          <surface>
            <contact>
              <ode/>
            </contact>
            <friction>
              <ode/>
              <torsional>
                <ode/>
              </torsional>
            </friction>
            <bounce/>
          </surface>
          <max_contacts>10</max_contacts>
        </collision>
        <collision name='crane_x7_shoulder_revolute_part_link_collision_1'>
          <pose>0 0 0.064 1.57079 -0 0</pose>
          <geometry>
            <cylinder>
              <length>0.0491</length>
              <radius>0.034</radius>
            </cylinder>
          </geometry>
          <surface>
            <contact>
              <ode/>
            </contact>
            <friction>
              <ode/>
              <torsional>
                <ode/>
              </torsional>
            </friction>
            <bounce/>
          </surface>
          <max_contacts>10</max_contacts>
        </collision>
        <visual name='crane_x7_shoulder_revolute_part_link_visual'>
          <pose>0 0 0 0 -0 3.14159</pose>
          <geometry>
            <mesh>
              <scale>1 1 1</scale>
              <uri>/home/shiokaze/catkin_ws/src/crane_x7_description/meshes/visual/base_revolute_part.stl</uri>
            </mesh>
          </geometry>
          <material>
            <script>
              <name>Gazebo/White</name>
              <uri>file://media/materials/scripts/gazebo.material</uri>
            </script>
          </material>
        </visual>
        <self_collide>0</self_collide>
        <enable_wind>0</enable_wind>
        <kinematic>0</kinematic>
      </link>
      <joint name='crane_x7_shoulder_revolute_part_tilt_joint' type='revolute'>
        <pose relative_to='crane_x7_shoulder_revolute_part_link'>0 0 0.064 0 -0 0</pose>
        <parent>crane_x7_shoulder_revolute_part_link</parent>
        <child>crane_x7_upper_arm_fixed_part_link</child>
        <axis>
          <xyz>0 -1 0</xyz>
          <limit>
            <lower>-1.57079</lower>
            <upper>1.57079</upper>
            <effort>10</effort>
            <velocity>4.81711</velocity>
          </limit>
          <dynamics>
            <damping>1e-06</damping>
            <friction>0.2</friction>
            <spring_reference>0</spring_reference>
            <spring_stiffness>0</spring_stiffness>
          </dynamics>
        </axis>
      </joint>
      <link name='crane_x7_upper_arm_fixed_part_link'>
        <pose relative_to='crane_x7_shoulder_revolute_part_tilt_joint'>0 0 0 0 -0 0</pose>
        <inertial>
          <pose>3.1e-05 1.9e-05 0.0342 1.57079 -0 0</pose>
          <mass>0.136</mass>
          <inertia>
            <ixx>0.000168</ixx>
            <ixy>2.05e-08</ixy>
            <ixz>-4e-07</ixz>
            <iyy>9.62e-05</iyy>
            <iyz>6.24e-08</iyz>
            <izz>0.000134</izz>
          </inertia>
        </inertial>
        <collision name='crane_x7_upper_arm_fixed_part_link_collision'>
          <pose>0 0 0 1.57079 -0 0</pose>
          <geometry>
            <mesh>
              <scale>1 1 1</scale>
              <uri>/home/shiokaze/catkin_ws/src/crane_x7_description/meshes/collision/rotating_link_type_1_fixed_part.stl</uri>
            </mesh>
          </geometry>
          <surface>
            <contact>
              <ode/>
            </contact>
            <friction>
              <ode/>
              <torsional>
                <ode/>
              </torsional>
            </friction>
            <bounce/>
          </surface>
          <max_contacts>10</max_contacts>
        </collision>
        <collision name='crane_x7_upper_arm_fixed_part_link_fixed_joint_lump__crane_x7_upper_arm_fixed_part_joint_cover_l_link_collision_1'>
          <pose>0 0.0316 0 -1.57079 0 0</pose>
          <geometry>
            <mesh>
              <scale>1 1 1</scale>
              <uri>/home/shiokaze/catkin_ws/src/crane_x7_description/meshes/visual/joint_cover.stl</uri>
            </mesh>
          </geometry>
          <surface>
            <contact>
              <ode/>
            </contact>
            <friction>
              <ode/>
              <torsional>
                <ode/>
              </torsional>
            </friction>
            <bounce/>
          </surface>
          <max_contacts>10</max_contacts>
        </collision>
        <collision name='crane_x7_upper_arm_fixed_part_link_fixed_joint_lump__crane_x7_upper_arm_fixed_part_joint_cover_r_link_collision_2'>
          <pose>0 -0.0316 0 1.57079 -0 0</pose>
          <geometry>
            <mesh>
              <scale>1 1 1</scale>
              <uri>/home/shiokaze/catkin_ws/src/crane_x7_description/meshes/visual/joint_cover.stl</uri>
            </mesh>
          </geometry>
          <surface>
            <contact>
              <ode/>
            </contact>
            <friction>
              <ode/>
              <torsional>
                <ode/>
              </torsional>
            </friction>
            <bounce/>
          </surface>
          <max_contacts>10</max_contacts>
        </collision>
        <visual name='crane_x7_upper_arm_fixed_part_link_visual'>
          <pose>0 0 0 1.57079 -0 0</pose>
          <geometry>
            <mesh>
              <scale>1 1 1</scale>
              <uri>/home/shiokaze/catkin_ws/src/crane_x7_description/meshes/visual/rotating_link_type_1_fixed_part.stl</uri>
            </mesh>
          </geometry>
          <material>
            <script>
              <name>Gazebo/White</name>
              <uri>file://media/materials/scripts/gazebo.material</uri>
            </script>
          </material>
        </visual>
        <visual name='crane_x7_upper_arm_fixed_part_link_fixed_joint_lump__crane_x7_upper_arm_fixed_part_joint_cover_l_link_visual_1'>
          <pose>0 0.0316 0 -1.57079 0 0</pose>
          <geometry>
            <mesh>
              <scale>1 1 1</scale>
              <uri>/home/shiokaze/catkin_ws/src/crane_x7_description/meshes/visual/joint_cover.stl</uri>
            </mesh>
          </geometry>
          <material>
            <script>
              <name>Gazebo/Red</name>
              <uri>file://media/materials/scripts/gazebo.material</uri>
            </script>
          </material>
        </visual>
        <visual name='crane_x7_upper_arm_fixed_part_link_fixed_joint_lump__crane_x7_upper_arm_fixed_part_joint_cover_r_link_visual_2'>
          <pose>0 -0.0316 0 1.57079 -0 0</pose>
          <geometry>
            <mesh>
              <scale>1 1 1</scale>
              <uri>/home/shiokaze/catkin_ws/src/crane_x7_description/meshes/visual/joint_cover.stl</uri>
            </mesh>
          </geometry>
          <material>
            <script>
              <name>Gazebo/Red</name>
              <uri>file://media/materials/scripts/gazebo.material</uri>
            </script>
          </material>
        </visual>
        <self_collide>0</self_collide>
        <enable_wind>0</enable_wind>
        <kinematic>0</kinematic>
      </link>
      <joint name='crane_x7_upper_arm_revolute_part_twist_joint' type='revolute'>
        <pose relative_to='crane_x7_upper_arm_fixed_part_link'>0 0 0.065 0 -0 0</pose>
        <parent>crane_x7_upper_arm_fixed_part_link</parent>
        <child>crane_x7_upper_arm_revolute_part_link</child>
        <axis>
          <xyz>0 0 1</xyz>
          <limit>
            <lower>-1.57079</lower>
            <upper>1.57079</upper>
            <effort>4</effort>
            <velocity>4.81711</velocity>
          </limit>
          <dynamics>
            <damping>1e-06</damping>
            <friction>0.2</friction>
            <spring_reference>0</spring_reference>
            <spring_stiffness>0</spring_stiffness>
          </dynamics>
        </axis>
      </joint>
      <link name='crane_x7_upper_arm_revolute_part_link'>
        <pose relative_to='crane_x7_upper_arm_revolute_part_twist_joint'>0 0 0 0 -0 0</pose>
        <inertial>
          <pose>-0.0137 -8.1e-05 0.0952 0 -0 0</pose>
          <mass>0.321</mass>
          <inertia>
            <ixx>0.00182</ixx>
            <ixy>7.54e-07</ixy>
            <ixz>-3.73e-05</ixz>
            <iyy>0.00188</iyy>
            <iyz>4.15e-06</iyz>
            <izz>0.000159</izz>
          </inertia>
        </inertial>
        <collision name='crane_x7_upper_arm_revolute_part_link_collision'>
          <pose>0 0 0 0 -0 0</pose>
          <geometry>
            <mesh>
              <scale>1 1 1</scale>
              <uri>/home/shiokaze/catkin_ws/src/crane_x7_description/meshes/collision/rotating_link_type_1_revolute_part.stl</uri>
            </mesh>
          </geometry>
          <surface>
            <contact>
              <ode/>
            </contact>
            <friction>
              <ode/>
              <torsional>
                <ode/>
              </torsional>
            </friction>
            <bounce/>
          </surface>
          <max_contacts>10</max_contacts>
        </collision>
        <visual name='crane_x7_upper_arm_revolute_part_link_visual'>
          <pose>0 0 0 0 -0 0</pose>
          <geometry>
            <mesh>
              <scale>1 1 1</scale>
              <uri>/home/shiokaze/catkin_ws/src/crane_x7_description/meshes/visual/rotating_link_type_1_revolute_part.stl</uri>
            </mesh>
          </geometry>
          <material>
            <script>
              <name>Gazebo/White</name>
              <uri>file://media/materials/scripts/gazebo.material</uri>
            </script>
          </material>
        </visual>
        <self_collide>0</self_collide>
        <enable_wind>0</enable_wind>
        <kinematic>0</kinematic>
      </link>
      <joint name='crane_x7_upper_arm_revolute_part_rotate_joint' type='revolute'>
        <pose relative_to='crane_x7_upper_arm_revolute_part_link'>0 0 0.185 0 -0 0</pose>
        <parent>crane_x7_upper_arm_revolute_part_link</parent>
        <child>crane_x7_lower_arm_fixed_part_link</child>
        <axis>
          <xyz>0 -1 0</xyz>
          <limit>
            <lower>-2.80718</lower>
            <upper>0.04141</upper>
            <effort>4</effort>
            <velocity>4.81711</velocity>
          </limit>
          <dynamics>
            <damping>1e-06</damping>
            <friction>0.2</friction>
            <spring_reference>0</spring_reference>
            <spring_stiffness>0</spring_stiffness>
          </dynamics>
        </axis>
      </joint>
      <link name='crane_x7_lower_arm_fixed_part_link'>
        <pose relative_to='crane_x7_upper_arm_revolute_part_rotate_joint'>0 0 0 0 -0 0</pose>
        <inertial>
          <pose>-0.00939 6.4e-05 0.0804 1.57079 -0 0</pose>
          <mass>0.222</mass>
          <inertia>
            <ixx>0.000489</ixx>
            <ixy>-3.9e-06</ixy>
            <ixz>8.29e-08</ixz>
            <iyy>0.000114</iyy>
            <iyz>2.82e-06</iyz>
            <izz>0.000503</izz>
          </inertia>
        </inertial>
        <collision name='crane_x7_lower_arm_fixed_part_link_collision'>
          <pose>0 0 0 1.57079 -0 0</pose>
          <geometry>
            <mesh>
              <scale>1 1 1</scale>
              <uri>/home/shiokaze/catkin_ws/src/crane_x7_description/meshes/collision/rotating_link_type_2_fixed_part.stl</uri>
            </mesh>
          </geometry>
          <surface>
            <contact>
              <ode/>
            </contact>
            <friction>
              <ode/>
              <torsional>
                <ode/>
              </torsional>
            </friction>
            <bounce/>
          </surface>
          <max_contacts>10</max_contacts>
        </collision>
        <collision name='crane_x7_lower_arm_fixed_part_link_fixed_joint_lump__crane_x7_lower_arm_fixed_part_joint_cover_l_link_collision_1'>
          <pose>0 0.025 0 -1.57079 0 0</pose>
          <geometry>
            <mesh>
              <scale>1 1 1</scale>
              <uri>/home/shiokaze/catkin_ws/src/crane_x7_description/meshes/visual/joint_cover.stl</uri>
            </mesh>
          </geometry>
          <surface>
            <contact>
              <ode/>
            </contact>
            <friction>
              <ode/>
              <torsional>
                <ode/>
              </torsional>
            </friction>
            <bounce/>
          </surface>
          <max_contacts>10</max_contacts>
        </collision>
        <collision name='crane_x7_lower_arm_fixed_part_link_fixed_joint_lump__crane_x7_lower_arm_fixed_part_joint_cover_r_link_collision_2'>
          <pose>0 -0.025 0 1.57079 -0 0</pose>
          <geometry>
            <mesh>
              <scale>1 1 1</scale>
              <uri>/home/shiokaze/catkin_ws/src/crane_x7_description/meshes/visual/joint_cover.stl</uri>
            </mesh>
          </geometry>
          <surface>
            <contact>
              <ode/>
            </contact>
            <friction>
              <ode/>
              <torsional>
                <ode/>
              </torsional>
            </friction>
            <bounce/>
          </surface>
          <max_contacts>10</max_contacts>
        </collision>
        <visual name='crane_x7_lower_arm_fixed_part_link_visual'>
          <pose>0 0 0 1.57079 -0 0</pose>
          <geometry>
            <mesh>
              <scale>1 1 1</scale>
              <uri>/home/shiokaze/catkin_ws/src/crane_x7_description/meshes/visual/rotating_link_type_2_fixed_part.stl</uri>
            </mesh>
          </geometry>
          <material>
            <script>
              <name>Gazebo/White</name>
              <uri>file://media/materials/scripts/gazebo.material</uri>
            </script>
          </material>
        </visual>
        <visual name='crane_x7_lower_arm_fixed_part_link_fixed_joint_lump__crane_x7_lower_arm_fixed_part_joint_cover_l_link_visual_1'>
          <pose>0 0.025 0 -1.57079 0 0</pose>
          <geometry>
            <mesh>
              <scale>1 1 1</scale>
              <uri>/home/shiokaze/catkin_ws/src/crane_x7_description/meshes/visual/joint_cover.stl</uri>
            </mesh>
          </geometry>
          <material>
            <script>
              <name>Gazebo/Red</name>
              <uri>file://media/materials/scripts/gazebo.material</uri>
            </script>
          </material>
        </visual>
        <visual name='crane_x7_lower_arm_fixed_part_link_fixed_joint_lump__crane_x7_lower_arm_fixed_part_joint_cover_r_link_visual_2'>
          <pose>0 -0.025 0 1.57079 -0 0</pose>
          <geometry>
            <mesh>
              <scale>1 1 1</scale>
              <uri>/home/shiokaze/catkin_ws/src/crane_x7_description/meshes/visual/joint_cover.stl</uri>
            </mesh>
          </geometry>
          <material>
            <script>
              <name>Gazebo/Red</name>
              <uri>file://media/materials/scripts/gazebo.material</uri>
            </script>
          </material>
        </visual>
        <self_collide>0</self_collide>
        <enable_wind>0</enable_wind>
        <kinematic>0</kinematic>
      </link>
      <joint name='crane_x7_lower_arm_fixed_part_joint' type='revolute'>
        <pose relative_to='crane_x7_lower_arm_fixed_part_link'>0 0 0.121 0 -0 0</pose>
        <parent>crane_x7_lower_arm_fixed_part_link</parent>
        <child>crane_x7_lower_arm_revolute_part_link</child>
        <axis>
          <xyz>0 0 1</xyz>
          <limit>
            <lower>-2.77343</lower>
            <upper>2.77343</upper>
            <effort>4</effort>
            <velocity>4.81711</velocity>
          </limit>
          <dynamics>
            <damping>1e-06</damping>
            <friction>0.2</friction>
            <spring_reference>0</spring_reference>
            <spring_stiffness>0</spring_stiffness>
          </dynamics>
        </axis>
      </joint>
      <link name='crane_x7_lower_arm_revolute_part_link'>
        <pose relative_to='crane_x7_lower_arm_fixed_part_joint'>0 0 0 0 -0 0</pose>
        <inertial>
          <pose>-8.4e-05 0.000462 0.0637 0 -0 0</pose>
          <mass>0.207</mass>
          <inertia>
            <ixx>0.00029</ixx>
            <ixy>1e-07</ixy>
            <ixz>-4.77e-07</ixz>
            <iyy>0.000257</iyy>
            <iyz>-1.69e-05</iyz>
            <izz>8.75e-05</izz>
          </inertia>
        </inertial>
        <collision name='crane_x7_lower_arm_revolute_part_link_collision'>
          <pose>0 0 0 0 -0 0</pose>
          <geometry>
            <mesh>
              <scale>1 1 1</scale>
              <uri>/home/shiokaze/catkin_ws/src/crane_x7_description/meshes/collision/rotating_link_type_2_revolute_part.stl</uri>
            </mesh>
          </geometry>
          <surface>
            <contact>
              <ode/>
            </contact>
            <friction>
              <ode/>
              <torsional>
                <ode/>
              </torsional>
            </friction>
            <bounce/>
          </surface>
          <max_contacts>10</max_contacts>
        </collision>
        <collision name='crane_x7_lower_arm_revolute_part_link_fixed_joint_lump__crane_x7_lower_arm_revolute_part_logo_symbol_l_link_collision_1'>
          <pose>0 0.0345 0.132 1.57079 1.57079 3.14159</pose>
          <geometry>
            <mesh>
              <scale>1 1 1</scale>
              <uri>/home/shiokaze/catkin_ws/src/crane_x7_description/meshes/visual/rtcorp_logo_rabbit.stl</uri>
            </mesh>
          </geometry>
          <surface>
            <contact>
              <ode/>
            </contact>
            <friction>
              <ode/>
              <torsional>
                <ode/>
              </torsional>
            </friction>
            <bounce/>
          </surface>
          <max_contacts>10</max_contacts>
        </collision>
        <collision name='crane_x7_lower_arm_revolute_part_link_fixed_joint_lump__crane_x7_lower_arm_revolute_part_logo_symbol_r_link_collision_2'>
          <pose>0 -0.0345 0.065 -1.57079 -1.57079 3.14159</pose>
          <geometry>
            <mesh>
              <scale>1 1 1</scale>
              <uri>/home/shiokaze/catkin_ws/src/crane_x7_description/meshes/visual/rtcorp_logo_rabbit.stl</uri>
            </mesh>
          </geometry>
          <surface>
            <contact>
              <ode/>
            </contact>
            <friction>
              <ode/>
              <torsional>
                <ode/>
              </torsional>
            </friction>
            <bounce/>
          </surface>
          <max_contacts>10</max_contacts>
        </collision>
        <collision name='crane_x7_lower_arm_revolute_part_link_fixed_joint_lump__crane_x7_lower_arm_revolute_part_logo_text_l_link_collision_3'>
          <pose>0 0.0345 0.095 1.57079 1.57079 3.14159</pose>
          <geometry>
            <mesh>
              <scale>1 1 1</scale>
              <uri>/home/shiokaze/catkin_ws/src/crane_x7_description/meshes/visual/rtcorp_logo_name.stl</uri>
            </mesh>
          </geometry>
          <surface>
            <contact>
              <ode/>
            </contact>
            <friction>
              <ode/>
              <torsional>
                <ode/>
              </torsional>
            </friction>
            <bounce/>
          </surface>
          <max_contacts>10</max_contacts>
        </collision>
        <collision name='crane_x7_lower_arm_revolute_part_link_fixed_joint_lump__crane_x7_lower_arm_revolute_part_logo_text_r_link_collision_4'>
          <pose>0 -0.0345 0.104 -1.57079 -1.57079 3.14159</pose>
          <geometry>
            <mesh>
              <scale>1 1 1</scale>
              <uri>/home/shiokaze/catkin_ws/src/crane_x7_description/meshes/visual/rtcorp_logo_name.stl</uri>
            </mesh>
          </geometry>
          <surface>
            <contact>
              <ode/>
            </contact>
            <friction>
              <ode/>
              <torsional>
                <ode/>
              </torsional>
            </friction>
            <bounce/>
          </surface>
          <max_contacts>10</max_contacts>
        </collision>
        <visual name='crane_x7_lower_arm_revolute_part_link_visual'>
          <pose>0 0 0 0 -0 0</pose>
          <geometry>
            <mesh>
              <scale>1 1 1</scale>
              <uri>/home/shiokaze/catkin_ws/src/crane_x7_description/meshes/visual/rotating_link_type_2_revolute_part.stl</uri>
            </mesh>
          </geometry>
          <material>
            <script>
              <name>Gazebo/White</name>
              <uri>file://media/materials/scripts/gazebo.material</uri>
            </script>
          </material>
        </visual>
        <visual name='crane_x7_lower_arm_revolute_part_link_fixed_joint_lump__crane_x7_lower_arm_revolute_part_logo_symbol_l_link_visual_1'>
          <pose>0 0.0345 0.132 1.57079 1.57079 3.14159</pose>
          <geometry>
            <mesh>
              <scale>1 1 1</scale>
              <uri>/home/shiokaze/catkin_ws/src/crane_x7_description/meshes/visual/rtcorp_logo_rabbit.stl</uri>
            </mesh>
          </geometry>
          <material>
            <script>
              <name>Gazebo/Red</name>
              <uri>file://media/materials/scripts/gazebo.material</uri>
            </script>
          </material>
        </visual>
        <visual name='crane_x7_lower_arm_revolute_part_link_fixed_joint_lump__crane_x7_lower_arm_revolute_part_logo_symbol_r_link_visual_2'>
          <pose>0 -0.0345 0.065 -1.57079 -1.57079 3.14159</pose>
          <geometry>
            <mesh>
              <scale>1 1 1</scale>
              <uri>/home/shiokaze/catkin_ws/src/crane_x7_description/meshes/visual/rtcorp_logo_rabbit.stl</uri>
            </mesh>
          </geometry>
          <material>
            <script>
              <name>Gazebo/Red</name>
              <uri>file://media/materials/scripts/gazebo.material</uri>
            </script>
          </material>
        </visual>
        <visual name='crane_x7_lower_arm_revolute_part_link_fixed_joint_lump__crane_x7_lower_arm_revolute_part_logo_text_l_link_visual_3'>
          <pose>0 0.0345 0.095 1.57079 1.57079 3.14159</pose>
          <geometry>
            <mesh>
              <scale>1 1 1</scale>
              <uri>/home/shiokaze/catkin_ws/src/crane_x7_description/meshes/visual/rtcorp_logo_name.stl</uri>
            </mesh>
          </geometry>
          <material>
            <script>
              <name>Gazebo/Black</name>
              <uri>file://media/materials/scripts/gazebo.material</uri>
            </script>
          </material>
        </visual>
        <visual name='crane_x7_lower_arm_revolute_part_link_fixed_joint_lump__crane_x7_lower_arm_revolute_part_logo_text_r_link_visual_4'>
          <pose>0 -0.0345 0.104 -1.57079 -1.57079 3.14159</pose>
          <geometry>
            <mesh>
              <scale>1 1 1</scale>
              <uri>/home/shiokaze/catkin_ws/src/crane_x7_description/meshes/visual/rtcorp_logo_name.stl</uri>
            </mesh>
          </geometry>
          <material>
            <script>
              <name>Gazebo/Black</name>
              <uri>file://media/materials/scripts/gazebo.material</uri>
            </script>
          </material>
        </visual>
        <self_collide>0</self_collide>
        <enable_wind>0</enable_wind>
        <kinematic>0</kinematic>
      </link>
      <joint name='crane_x7_lower_arm_revolute_part_joint' type='revolute'>
        <pose relative_to='crane_x7_lower_arm_revolute_part_link'>0 0 0.129 0 -0 0</pose>
        <parent>crane_x7_lower_arm_revolute_part_link</parent>
        <child>crane_x7_wrist_link</child>
        <axis>
          <xyz>0 -1 0</xyz>
          <limit>
            <lower>-1.57079</lower>
            <upper>1.57079</upper>
            <effort>4</effort>
            <velocity>4.81711</velocity>
          </limit>
          <dynamics>
            <damping>1e-06</damping>
            <friction>0.2</friction>
            <spring_reference>0</spring_reference>
            <spring_stiffness>0</spring_stiffness>
          </dynamics>
        </axis>
      </joint>
      <link name='crane_x7_wrist_link'>
        <pose relative_to='crane_x7_lower_arm_revolute_part_joint'>0 0 0 0 -0 0</pose>
        <inertial>
          <pose>0.0061 0.000826 -0.00355 1.57079 -0 0</pose>
          <mass>0.14</mass>
          <inertia>
            <ixx>4.01e-05</ixx>
            <ixy>-2.91e-06</ixy>
            <ixz>6.39e-07</ixz>
            <iyy>6.13e-05</iyy>
            <iyz>-4.9e-07</iyz>
            <izz>7.35e-05</izz>
          </inertia>
        </inertial>
        <collision name='crane_x7_wrist_link_collision'>
          <pose>0 0 0 1.57079 -0 0</pose>
          <geometry>
            <mesh>
              <scale>1 1 1</scale>
              <uri>/home/shiokaze/catkin_ws/src/crane_x7_description/meshes/collision/wrist.stl</uri>
            </mesh>
          </geometry>
          <surface>
            <contact>
              <ode/>
            </contact>
            <friction>
              <ode/>
              <torsional>
                <ode/>
              </torsional>
            </friction>
            <bounce/>
          </surface>
          <max_contacts>10</max_contacts>
        </collision>
        <visual name='crane_x7_wrist_link_visual'>
          <pose>0 0 0 1.57079 -0 0</pose>
          <geometry>
            <mesh>
              <scale>1 1 1</scale>
              <uri>/home/shiokaze/catkin_ws/src/crane_x7_description/meshes/visual/wrist.stl</uri>
            </mesh>
          </geometry>
          <material>
            <script>
              <name>Gazebo/White</name>
              <uri>file://media/materials/scripts/gazebo.material</uri>
            </script>
          </material>
        </visual>
        <self_collide>0</self_collide>
        <enable_wind>0</enable_wind>
        <kinematic>0</kinematic>
      </link>
      <joint name='crane_x7_wrist_joint' type='revolute'>
        <pose relative_to='crane_x7_wrist_link'>0 0 0.019 0 -0 0</pose>
        <parent>crane_x7_wrist_link</parent>
        <child>crane_x7_gripper_base_link</child>
        <axis>
          <xyz>0 0 1</xyz>
          <limit>
            <lower>-2.96365</lower>
            <upper>2.97132</upper>
            <effort>4</effort>
            <velocity>4.81711</velocity>
          </limit>
          <dynamics>
            <damping>1e-06</damping>
            <friction>0.2</friction>
            <spring_reference>0</spring_reference>
            <spring_stiffness>0</spring_stiffness>
          </dynamics>
        </axis>
      </joint>
      <link name='crane_x7_gripper_base_link'>
        <pose relative_to='crane_x7_wrist_joint'>0 0 0 0 -0 0</pose>
        <inertial>
          <pose>1.8e-05 0.036859 0.01098 0 -0 0</pose>
          <mass>0.721</mass>
          <inertia>
            <ixx>0.00125476</ixx>
            <ixy>4.00634e-07</ixy>
            <ixz>1.32676e-07</ixz>
            <iyy>0.00105542</iyy>
            <iyz>5.4486e-05</iyz>
            <izz>0.00125164</izz>
          </inertia>
        </inertial>
        <collision name='crane_x7_gripper_base_link_collision'>
          <pose>0 0 0 0 -0 0</pose>
          <geometry>
            <mesh>
              <scale>1 1 1</scale>
              <uri>/home/shiokaze/catkin_ws/src/crane_x7_description/meshes/collision/wide_two_finger_gripper_actuator.stl</uri>
            </mesh>
          </geometry>
          <surface>
            <contact>
              <ode/>
            </contact>
            <friction>
              <ode/>
              <torsional>
                <ode/>
              </torsional>
            </friction>
            <bounce/>
          </surface>
          <max_contacts>10</max_contacts>
        </collision>
        <collision name='crane_x7_gripper_base_link_fixed_joint_lump__camera_base_collision_1'>
          <pose>0 0.0445 0.021525 1.57079 -1.57079 3.14159</pose>
          <geometry>
            <box>
              <size>0.02505 0.09 0.025</size>
            </box>
          </geometry>
          <max_contacts>10</max_contacts>
          <surface>
            <contact>
              <ode/>
            </contact>
            <bounce/>
            <friction>
              <torsional>
                <ode/>
              </torsional>
              <ode/>
            </friction>
          </surface>
        </collision>
        <visual name='crane_x7_gripper_base_link_visual'>
          <pose>0 0 0 0 -0 0</pose>
          <geometry>
            <mesh>
              <scale>1 1 1</scale>
              <uri>/home/shiokaze/catkin_ws/src/crane_x7_description/meshes/visual/wide_two_finger_gripper_actuator.stl</uri>
            </mesh>
          </geometry>
          <material>
            <script>
              <name>Gazebo/Red</name>
              <uri>file://media/materials/scripts/gazebo.material</uri>
            </script>
          </material>
        </visual>
        <visual name='crane_x7_gripper_base_link_fixed_joint_lump__camera_base_visual_1'>
          <pose>0 0.0445 0.021525 1.57079 -1.57079 3.14159</pose>
          <geometry>
            <box>
              <size>0.02505 0.09 0.025</size>
            </box>
          </geometry>
        </visual>
        <sensor name='camera1' type='depth'>
          <update_rate>30</update_rate>
          <camera name='depth_camera'>
            <horizontal_fov>1.21126</horizontal_fov>
            <image>
              <width>640</width>
              <height>480</height>
              <format>B8G8R8</format>
            </image>
            <clip>
              <near>0.02</near>
              <far>300</far>
            </clip>
          </camera>
          <plugin name='camera_plugin' filename='libgazebo_ros_openni_kinect.so'>
            <baseline>0.2</baseline>
            <alwaysOn>1</alwaysOn>
            <updateRate>0.0</updateRate>
            <cameraName>camera</cameraName>
            <imageTopicName>fake_cam_color/image_raw</imageTopicName>
            <depthImageTopicName>depth/image_raw</depthImageTopicName>
            <pointCloudTopicName>depth/color/points</pointCloudTopicName>
            <frameName>camera_depth_optical_frame</frameName>
            <pointCloudCutoff>0.105</pointCloudCutoff>
            <pointCloudCutoffMax>10.0</pointCloudCutoffMax>
            <cameraInfoTopicName>fake_cam_color/camera_info</cameraInfoTopicName>
            <depthImageCameraInfoTopicName>depth/camera_info</depthImageCameraInfoTopicName>
            <hackBaseline>0.07</hackBaseline>
            <distortionK1>0.0</distortionK1>
            <distortionK2>0.0</distortionK2>
            <distortionK3>0.0</distortionK3>
            <distortionT1>0.0</distortionT1>
            <distortionT2>0.0</distortionT2>
            <robotNamespace>/</robotNamespace>
          </plugin>
          <pose>0.0175 0.0445 0.02985 3.14159 -1.57079 1.57079</pose>
        </sensor>
        <sensor name='camera2' type='depth'>
          <update_rate>30</update_rate>
          <camera name='color_camera'>
            <horizontal_fov>1.21126</horizontal_fov>
            <image>
              <width>640</width>
              <height>480</height>
              <format>B8G8R8</format>
            </image>
            <clip>
              <near>0.02</near>
              <far>300</far>
            </clip>
          </camera>
          <plugin name='camera_plugin' filename='libgazebo_ros_openni_kinect.so'>
            <baseline>0.2</baseline>
            <alwaysOn>1</alwaysOn>
            <updateRate>0.0</updateRate>
            <cameraName>camera</cameraName>
            <imageTopicName>color/image_raw</imageTopicName>
            <depthImageTopicName>aligned_depth_to_color/image_raw</depthImageTopicName>
            <cameraInfoTopicName>color/camera_info</cameraInfoTopicName>
            <depthImageCameraInfoTopicName>aligned_depth_to_color/camera_info</depthImageCameraInfoTopicName>
            <hackBaseline>0.07</hackBaseline>
            <distortionK1>0.0</distortionK1>
            <distortionK2>0.0</distortionK2>
            <distortionK3>0.0</distortionK3>
            <distortionT1>0.0</distortionT1>
            <distortionT2>0.0</distortionT2>
            <robotNamespace>/</robotNamespace>
          </plugin>
          <pose>0.0325 0.0445 0.02985 3.14159 -1.57079 1.57079</pose>
        </sensor>
        <self_collide>0</self_collide>
        <enable_wind>0</enable_wind>
        <kinematic>0</kinematic>
      </link>
      <joint name='crane_x7_gripper_finger_a_joint' type='revolute'>
        <pose relative_to='crane_x7_gripper_base_link'>-0.012 0 0.024 0 -0 0</pose>
        <parent>crane_x7_gripper_base_link</parent>
        <child>crane_x7_gripper_finger_a_link</child>
        <axis>
          <xyz>0 -1 0</xyz>
          <limit>
            <lower>0.0046</lower>
            <upper>1.62601</upper>
            <effort>4</effort>
            <velocity>4.81711</velocity>
          </limit>
          <dynamics>
            <damping>1e-06</damping>
            <friction>0.8</friction>
            <spring_reference>0</spring_reference>
            <spring_stiffness>0</spring_stiffness>
          </dynamics>
        </axis>
      </joint>
      <link name='crane_x7_gripper_finger_a_link'>
        <pose relative_to='crane_x7_gripper_finger_a_joint'>0 0 0 0 -0 0</pose>
        <inertial>
          <pose>-0.00265 0.00354 0.0269 1.57079 -0 0</pose>
          <mass>0.0158</mass>
          <inertia>
            <ixx>1.01e-05</ixx>
            <ixy>-1.97e-07</ixy>
            <ixz>-9.89e-08</ixz>
            <iyy>4.95e-06</iyy>
            <iyz>5.37e-07</iyz>
            <izz>6.24e-06</izz>
          </inertia>
        </inertial>
        <collision name='crane_x7_gripper_finger_a_link_collision'>
          <pose>0 0 0 1.57079 -0 0</pose>
          <geometry>
            <mesh>
              <scale>1 1 1</scale>
              <uri>/home/shiokaze/catkin_ws/src/crane_x7_description/meshes/collision/wide_two_finger_gripper_finger_a.stl</uri>
            </mesh>
          </geometry>
          <surface>
            <contact>
              <ode/>
            </contact>
            <friction>
              <ode>
                <mu>0.8</mu>
                <mu2>0.8</mu2>
              </ode>
              <torsional>
                <ode/>
              </torsional>
            </friction>
            <bounce/>
          </surface>
          <max_contacts>10</max_contacts>
        </collision>
        <visual name='crane_x7_gripper_finger_a_link_visual'>
          <pose>0 0 0 1.57079 -0 0</pose>
          <geometry>
            <mesh>
              <scale>1 1 1</scale>
              <uri>/home/shiokaze/catkin_ws/src/crane_x7_description/meshes/visual/wide_two_finger_gripper_finger_a.stl</uri>
            </mesh>
          </geometry>
          <material>
            <script>
              <name>Gazebo/Red</name>
              <uri>file://media/materials/scripts/gazebo.material</uri>
            </script>
          </material>
        </visual>
        <self_collide>0</self_collide>
        <enable_wind>0</enable_wind>
        <kinematic>0</kinematic>
      </link>
      <joint name='crane_x7_gripper_finger_b_joint' type='revolute'>
        <pose relative_to='crane_x7_gripper_base_link'>0.012 0 0.024 0 -0 0</pose>
        <parent>crane_x7_gripper_base_link</parent>
        <child>crane_x7_gripper_finger_b_link</child>
        <axis>
          <xyz>0 1 0</xyz>
          <limit>
            <lower>0.0046</lower>
            <upper>1.62601</upper>
            <effort>4</effort>
            <velocity>4.81711</velocity>
          </limit>
          <dynamics>
            <damping>1e-06</damping>
            <friction>0.8</friction>
            <spring_reference>0</spring_reference>
            <spring_stiffness>0</spring_stiffness>
          </dynamics>
        </axis>
      </joint>
      <link name='crane_x7_gripper_finger_b_link'>
        <pose relative_to='crane_x7_gripper_finger_b_joint'>0 0 0 0 -0 0</pose>
        <inertial>
          <pose>0.00301 0.00285 0.0309 1.57079 -0 0</pose>
          <mass>0.0139</mass>
          <inertia>
            <ixx>7.48e-06</ixx>
            <ixy>3.61e-07</ixy>
            <ixz>6.34e-08</ixz>
            <iyy>4.09e-06</iyy>
            <iyz>2.28e-07</iyz>
            <izz>4.37e-06</izz>
          </inertia>
        </inertial>
        <collision name='crane_x7_gripper_finger_b_link_collision'>
          <pose>0 0 0 1.57079 -0 0</pose>
          <geometry>
            <mesh>
              <scale>1 1 1</scale>
              <uri>/home/shiokaze/catkin_ws/src/crane_x7_description/meshes/collision/wide_two_finger_gripper_finger_b.stl</uri>
            </mesh>
          </geometry>
          <surface>
            <contact>
              <ode/>
            </contact>
            <friction>
              <ode>
                <mu>0.8</mu>
                <mu2>0.8</mu2>
              </ode>
              <torsional>
                <ode/>
              </torsional>
            </friction>
            <bounce/>
          </surface>
          <max_contacts>10</max_contacts>
        </collision>
        <visual name='crane_x7_gripper_finger_b_link_visual'>
          <pose>0 0 0 1.57079 -0 0</pose>
          <geometry>
            <mesh>
              <scale>1 1 1</scale>
              <uri>/home/shiokaze/catkin_ws/src/crane_x7_description/meshes/visual/wide_two_finger_gripper_finger_b.stl</uri>
            </mesh>
          </geometry>
          <material>
            <script>
              <name>Gazebo/Red</name>
              <uri>file://media/materials/scripts/gazebo.material</uri>
            </script>
          </material>
        </visual>
        <self_collide>0</self_collide>
        <enable_wind>0</enable_wind>
        <kinematic>0</kinematic>
      </link>
      <plugin name='gazebo_ros_control' filename='libgazebo_ros_control.so'>
        <robotNamespace>/crane_x7</robotNamespace>
        <robotSimType>gazebo_ros_control/DefaultRobotHWSim</robotSimType>
        <legacyModeNS>0</legacyModeNS>
      </plugin>
      <static>0</static>
      <plugin name='crane_x7_gripper_mimic_joint' filename='libroboticsgroup_upatras_gazebo_mimic_joint_plugin.so'>
        <joint>crane_x7_gripper_finger_a_joint</joint>
        <mimicJoint>crane_x7_gripper_finger_b_joint</mimicJoint>
        <multiplier>1</multiplier>
        <robotNamespace>/</robotNamespace>
      </plugin>
      <pose>0 0 1.02 0 -0 0</pose>
    </model>
    <model name='fork'>
      <link name='link_0'>
        <inertial>
          <mass>0.046813</mass>
          <inertia>
            <ixx>1.251e-05</ixx>
            <ixy>0</ixy>
            <ixz>1.626e-05</ixz>
            <iyy>0.00015998</iyy>
            <iyz>0</iyz>
            <izz>0.00015083</izz>
          </inertia>
          <pose>0.07 0 0 0 -0 0</pose>
        </inertial>
        <pose>0 0 0.0325 0 -0 0</pose>
        <gravity>1</gravity>
        <self_collide>0</self_collide>
        <kinematic>0</kinematic>
        <enable_wind>0</enable_wind>
        <visual name='visual'>
          <pose>0 0 0 0 -0 0</pose>
          <geometry>
            <mesh>
              <uri>/home/shiokaze/catkin_ws/src/honey/models/meshes/fork.stl</uri>
              <scale>1 1 1</scale>
            </mesh>
          </geometry>
          <material>
            <lighting>1</lighting>
            <script>
              <uri>file://media/materials/scripts/gazebo.material</uri>
              <name>Gazebo/Grey</name>
            </script>
            <shader type='pixel'>
              <normal_map>__default__</normal_map>
            </shader>
            <ambient>0.3 0.3 0.3 1</ambient>
            <diffuse>0.7 0.7 0.7 1</diffuse>
            <specular>0.01 0.01 0.01 1</specular>
            <emissive>0 0 0 1</emissive>
          </material>
          <transparency>0</transparency>
          <cast_shadows>1</cast_shadows>
        </visual>
        <collision name='collision'>
          <laser_retro>0</laser_retro>
          <max_contacts>10</max_contacts>
          <pose>0 0 0 0 -0 0</pose>
          <geometry>
            <mesh>
              <uri>/home/shiokaze/catkin_ws/src/honey/models/meshes/fork.stl</uri>
              <scale>1 1 1</scale>
            </mesh>
          </geometry>
          <surface>
            <friction>
              <ode>
                <mu>1</mu>
                <mu2>1</mu2>
                <fdir1>0 0 0</fdir1>
                <slip1>0</slip1>
                <slip2>0</slip2>
              </ode>
              <torsional>
                <coefficient>1</coefficient>
                <patch_radius>0</patch_radius>
                <surface_radius>0</surface_radius>
                <use_patch_radius>1</use_patch_radius>
                <ode>
                  <slip>0</slip>
                </ode>
              </torsional>
            </friction>
            <bounce>
              <restitution_coefficient>0</restitution_coefficient>
              <threshold>1e+06</threshold>
            </bounce>
            <contact>
              <collide_without_contact>0</collide_without_contact>
              <collide_without_contact_bitmask>1</collide_without_contact_bitmask>
              <collide_bitmask>1</collide_bitmask>
              <ode>
                <soft_cfm>0</soft_cfm>
                <soft_erp>0.2</soft_erp>
                <kp>1e+13</kp>
                <kd>1</kd>
                <max_vel>0.01</max_vel>
                <min_depth>0</min_depth>
              </ode>
              <bullet>
                <split_impulse>1</split_impulse>
                <split_impulse_penetration_threshold>-0.01</split_impulse_penetration_threshold>
                <soft_cfm>0</soft_cfm>
                <soft_erp>0.2</soft_erp>
                <kp>1e+13</kp>
                <kd>1</kd>
              </bullet>
            </contact>
          </surface>
        </collision>
      </link>
      <static>0</static>
      <allow_auto_disable>1</allow_auto_disable>
      <pose>0.034901 0.634593 0 0 -0 0</pose>
    </model>
    <state world_name='CRANE-X7 with Table'>
      <sim_time>33 237000000</sim_time>
      <real_time>48 350613913</real_time>
      <wall_time>1667916177 561841701</wall_time>
      <iterations>33237</iterations>
      <model name='crane_x7'>
        <pose>0 0 1.02 1e-05 -1e-06 0</pose>
        <scale>1 1 1</scale>
        <link name='base_link'>
          <pose>0 0 1.02 1e-05 -1e-06 0</pose>
          <velocity>0 -0 -0 -6e-06 -1e-05 -3e-06</velocity>
          <acceleration>3.7e-05 -7e-06 3.8e-05 -0.001794 0.003616 -0.003568</acceleration>
          <wrench>1.4e-05 -3e-06 1.5e-05 0 -0 0</wrench>
        </link>
        <link name='crane_x7_gripper_base_link'>
          <pose>-0.000553 6.5e-05 1.64399 -0.000292 -0.00189 -0.005162</pose>
          <velocity>0.000114 -3e-06 3e-06 -2e-06 6.5e-05 9.2e-05</velocity>
          <acceleration>0.015337 -0.000908 -0.0005 -2.71657 0.157283 0.191202</acceleration>
          <wrench>0.011058 -0.000655 -0.00036 0 -0 0</wrench>
        </link>
        <link name='crane_x7_gripper_finger_a_link'>
          <pose>-0.012598 0.000135 1.66797 -0.000293 -0.00649 -0.00516</pose>
          <velocity>0.000115 -4e-06 4e-06 -3e-06 6.4e-05 9.5e-05</velocity>
          <acceleration>0.020775 -0.002243 0.000406 0.732395 -0.358862 0.892318</acceleration>
          <wrench>0.000328 -3.5e-05 6e-06 0 -0 0</wrench>
        </link>
        <link name='crane_x7_gripper_finger_b_link'>
          <pose>0.011401 1.1e-05 1.66802 -0.000292 0.00271 -0.005163</pose>
          <velocity>0.000114 -1e-06 3e-06 -1e-06 9.7e-05 9.4e-05</velocity>
          <acceleration>0.021332 -0.000691 -0.002232 -1.91014 1.08578 -2.89998</acceleration>
          <wrench>0.000297 -1e-05 -3.1e-05 0 -0 0</wrench>
        </link>
        <link name='crane_x7_lower_arm_fixed_part_link'>
          <pose>-0.000503 3.3e-05 1.375 -0.00011 -6e-05 -0.000436</pose>
          <velocity>2.7e-05 -3e-06 -1e-06 6e-06 0.000502 -0.000515</velocity>
          <acceleration>0.003529 0.002884 0.000206 -0.043901 0.083668 -0.226388</acceleration>
          <wrench>0.000783 0.00064 4.6e-05 0 -0 0</wrench>
        </link>
        <link name='crane_x7_lower_arm_revolute_part_link'>
          <pose>-0.00051 4.9e-05 1.496 -0.00012 -5.7e-05 -0.001669</pose>
          <velocity>7.2e-05 -3e-06 1e-06 2e-06 0.00036 -0.000587</velocity>
          <acceleration>0.011041 -0.000494 -0.000155 0.061565 -0.01623 -0.153454</acceleration>
          <wrench>0.002285 -0.000102 -3.2e-05 0 -0 0</wrench>
        </link>
        <link name='crane_x7_shoulder_revolute_part_link'>
          <pose>0 3e-06 1.061 -5e-06 3e-06 -0.002182</pose>
          <velocity>4e-06 -1e-06 0 2e-06 2e-06 -0.000697</velocity>
          <acceleration>-0.00134 3.6e-05 -3.2e-05 0.048826 -0.031831 -0.47259</acceleration>
          <wrench>-0.000339 9e-06 -8e-06 0 -0 0</wrench>
        </link>
        <link name='crane_x7_upper_arm_fixed_part_link'>
          <pose>0 7e-06 1.125 -4.5e-05 -0.002014 -0.002182</pose>
          <velocity>4e-06 -1e-06 0 9e-06 0.000171 -0.000638</velocity>
          <acceleration>-0.001442 0.000184 -0.000115 1.19559 -0.03777 -0.451791</acceleration>
          <wrench>-0.000196 2.5e-05 -1.6e-05 0 -0 0</wrench>
        </link>
        <link name='crane_x7_upper_arm_revolute_part_link'>
          <pose>-0.00013 1e-05 1.19 -0.00011 -0.002016 -0.000435</pose>
          <velocity>1.8e-05 -3e-06 1e-06 6e-06 0.00013 -0.000541</velocity>
          <acceleration>-0.001454 0.004876 -0.000269 -2.32948 0.124563 -0.331698</acceleration>
          <wrench>-0.000467 0.001565 -8.6e-05 0 -0 0</wrench>
        </link>
        <link name='crane_x7_wrist_link'>
          <pose>-0.000518 6.4e-05 1.625 -8.5e-05 -0.00186 -0.001669</pose>
          <velocity>0.000111 -3e-06 3e-06 -3e-06 0.000188 -0.000584</velocity>
          <acceleration>0.015505 -0.002457 -0.000997 0.391228 -0.095677 0.819639</acceleration>
          <wrench>0.002171 -0.000344 -0.00014 0 -0 0</wrench>
        </link>
      </model>
      <model name='fork'>
        <pose>0.4 0 1.02 0 -0 0</pose>
        <scale>1 1 1</scale>
        <link name='link_0'>
          <pose>0.4 0 1.0525 0 -0 0</pose>
          <velocity>-0.000213 0.001167 -0.00092 -0.103414 0.002717 0.027426</velocity>
          <acceleration>-0.635919 2.07668 -2.38894 -1.4768 -0.049462 2.12753</acceleration>
          <wrench>-0.029769 0.097216 -0.111834 0 -0 0</wrench>
        </link>
      </model>
      <model name='ground_plane'>
        <pose>0 0 0 0 -0 0</pose>
        <scale>1 1 1</scale>
        <link name='ground_plane::link'>
          <pose>0 0 0 0 -0 0</pose>
          <velocity>0 0 0 0 -0 0</velocity>
          <acceleration>0 0 0 0 -0 0</acceleration>
          <wrench>0 0 0 0 -0 0</wrench>
        </link>
      </model>
      <model name='table'>
        <pose>0.29 0 0 0 -0 1.5708</pose>
        <scale>1 1 1</scale>
        <link name='table::link'>
          <pose>0.29 0 0 0 -0 1.5708</pose>
          <velocity>0 0 0 0 -0 0</velocity>
          <acceleration>0 0 0 0 -0 0</acceleration>
          <wrench>0 0 0 0 -0 0</wrench>
        </link>
      </model>
      <light name='sun'>
        <pose>0 0 10 0 -0 0</pose>
      </light>
    </state>
    <gui fullscreen='0'>
      <camera name='user_camera'>
        <pose>1.56523 -1.58554 1.71625 0 0.275643 2.35619</pose>
        <view_controller>orbit</view_controller>
        <projection_type>perspective</projection_type>
      </camera>
    </gui>
  </world>
</sdf>
